[2024-05-10T14:46:46.623+0000] {local_task_job_runner.py:120} INFO - ::group::Pre task execution logs
[2024-05-10T14:46:46.633+0000] {taskinstance.py:2073} INFO - Dependencies all met for dep_context=non-requeueable deps ti=<TaskInstance: 1_init_once_seed_data.load_seed_data_once manual__2024-05-10T14:46:44.902255+00:00 [queued]>
[2024-05-10T14:46:46.636+0000] {taskinstance.py:2073} INFO - Dependencies all met for dep_context=requeueable deps ti=<TaskInstance: 1_init_once_seed_data.load_seed_data_once manual__2024-05-10T14:46:44.902255+00:00 [queued]>
[2024-05-10T14:46:46.637+0000] {taskinstance.py:2303} INFO - Starting attempt 1 of 1
[2024-05-10T14:46:46.642+0000] {taskinstance.py:2327} INFO - Executing <Task(BashOperator): load_seed_data_once> on 2024-05-10 14:46:44.902255+00:00
[2024-05-10T14:46:46.646+0000] {warnings.py:110} WARNING - /home/***/.local/lib/python3.12/site-packages/***/task/task_runner/standard_task_runner.py:61: DeprecationWarning: This process (pid=64) is multi-threaded, use of fork() may lead to deadlocks in the child.
  pid = os.fork()

[2024-05-10T14:46:46.648+0000] {standard_task_runner.py:63} INFO - Started process 66 to run task
[2024-05-10T14:46:46.647+0000] {standard_task_runner.py:90} INFO - Running: ['***', 'tasks', 'run', '1_init_once_seed_data', 'load_seed_data_once', 'manual__2024-05-10T14:46:44.902255+00:00', '--job-id', '80', '--raw', '--subdir', 'DAGS_FOLDER/init.py', '--cfg-path', '/tmp/tmp6_q7wqen']
[2024-05-10T14:46:46.649+0000] {standard_task_runner.py:91} INFO - Job 80: Subtask load_seed_data_once
[2024-05-10T14:46:46.676+0000] {task_command.py:426} INFO - Running <TaskInstance: 1_init_once_seed_data.load_seed_data_once manual__2024-05-10T14:46:44.902255+00:00 [running]> on host e4fe3fcdc4ab
[2024-05-10T14:46:46.732+0000] {taskinstance.py:2644} INFO - Exporting env vars: AIRFLOW_CTX_DAG_OWNER='***' AIRFLOW_CTX_DAG_ID='1_init_once_seed_data' AIRFLOW_CTX_TASK_ID='load_seed_data_once' AIRFLOW_CTX_EXECUTION_DATE='2024-05-10T14:46:44.902255+00:00' AIRFLOW_CTX_TRY_NUMBER='1' AIRFLOW_CTX_DAG_RUN_ID='manual__2024-05-10T14:46:44.902255+00:00'
[2024-05-10T14:46:46.733+0000] {taskinstance.py:430} INFO - ::endgroup::
[2024-05-10T14:46:46.733+0000] {subprocess.py:63} INFO - Tmp dir root location: /tmp
[2024-05-10T14:46:46.734+0000] {subprocess.py:75} INFO - Running command: ['/usr/bin/bash', '-c', 'cd /dbt && dbt seed --profiles-dir .']
[2024-05-10T14:46:46.738+0000] {subprocess.py:86} INFO - Output:
[2024-05-10T14:46:48.178+0000] {subprocess.py:93} INFO - [0m14:46:48  Running with dbt=1.7.14
[2024-05-10T14:46:48.182+0000] {subprocess.py:93} INFO - [0m14:46:48  Encountered an error:
[2024-05-10T14:46:48.182+0000] {subprocess.py:93} INFO - Parsing Error
[2024-05-10T14:46:48.183+0000] {subprocess.py:93} INFO -   Env var required but not provided: 'dbt_account'
[2024-05-10T14:46:49.609+0000] {subprocess.py:97} INFO - Command exited with return code 2
[2024-05-10T14:46:49.610+0000] {taskinstance.py:441} INFO - ::group::Post task execution logs
[2024-05-10T14:46:49.615+0000] {taskinstance.py:2890} ERROR - Task failed with exception
Traceback (most recent call last):
  File "/home/airflow/.local/lib/python3.12/site-packages/airflow/models/taskinstance.py", line 465, in _execute_task
    result = _execute_callable(context=context, **execute_callable_kwargs)
             ^^^^^^^^^^^^^^^^^^^^^^^^^^^^^^^^^^^^^^^^^^^^^^^^^^^^^^^^^^^^^
  File "/home/airflow/.local/lib/python3.12/site-packages/airflow/models/taskinstance.py", line 432, in _execute_callable
    return execute_callable(context=context, **execute_callable_kwargs)
           ^^^^^^^^^^^^^^^^^^^^^^^^^^^^^^^^^^^^^^^^^^^^^^^^^^^^^^^^^^^^
  File "/home/airflow/.local/lib/python3.12/site-packages/airflow/models/baseoperator.py", line 400, in wrapper
    return func(self, *args, **kwargs)
           ^^^^^^^^^^^^^^^^^^^^^^^^^^^
  File "/home/airflow/.local/lib/python3.12/site-packages/airflow/operators/bash.py", line 243, in execute
    raise AirflowException(
airflow.exceptions.AirflowException: Bash command failed. The command returned a non-zero exit code 2.
[2024-05-10T14:46:49.617+0000] {taskinstance.py:1205} INFO - Marking task as FAILED. dag_id=1_init_once_seed_data, task_id=load_seed_data_once, execution_date=20240510T144644, start_date=20240510T144646, end_date=20240510T144649
[2024-05-10T14:46:49.623+0000] {standard_task_runner.py:110} ERROR - Failed to execute job 80 for task load_seed_data_once (Bash command failed. The command returned a non-zero exit code 2.; 66)
[2024-05-10T14:46:49.637+0000] {local_task_job_runner.py:240} INFO - Task exited with return code 1
[2024-05-10T14:46:49.646+0000] {taskinstance.py:3482} INFO - 0 downstream tasks scheduled from follow-on schedule check
[2024-05-10T14:46:49.647+0000] {local_task_job_runner.py:222} INFO - ::endgroup::
