[2024-05-10T15:29:37.976+0000] {local_task_job_runner.py:120} INFO - ::group::Pre task execution logs
[2024-05-10T15:29:37.988+0000] {taskinstance.py:2073} INFO - Dependencies all met for dep_context=non-requeueable deps ti=<TaskInstance: 1_init_once_seed_data.load_seed_data_once manual__2024-05-10T15:29:36.514489+00:00 [queued]>
[2024-05-10T15:29:37.992+0000] {taskinstance.py:2073} INFO - Dependencies all met for dep_context=requeueable deps ti=<TaskInstance: 1_init_once_seed_data.load_seed_data_once manual__2024-05-10T15:29:36.514489+00:00 [queued]>
[2024-05-10T15:29:37.992+0000] {taskinstance.py:2303} INFO - Starting attempt 1 of 1
[2024-05-10T15:29:37.998+0000] {taskinstance.py:2327} INFO - Executing <Task(BashOperator): load_seed_data_once> on 2024-05-10 15:29:36.514489+00:00
[2024-05-10T15:29:38.001+0000] {warnings.py:110} WARNING - /home/***/.local/lib/python3.12/site-packages/***/task/task_runner/standard_task_runner.py:61: DeprecationWarning: This process (pid=71) is multi-threaded, use of fork() may lead to deadlocks in the child.
  pid = os.fork()

[2024-05-10T15:29:38.003+0000] {standard_task_runner.py:63} INFO - Started process 73 to run task
[2024-05-10T15:29:38.003+0000] {standard_task_runner.py:90} INFO - Running: ['***', 'tasks', 'run', '1_init_once_seed_data', 'load_seed_data_once', 'manual__2024-05-10T15:29:36.514489+00:00', '--job-id', '101', '--raw', '--subdir', 'DAGS_FOLDER/init.py', '--cfg-path', '/tmp/tmpkr83p23j']
[2024-05-10T15:29:38.004+0000] {standard_task_runner.py:91} INFO - Job 101: Subtask load_seed_data_once
[2024-05-10T15:29:38.029+0000] {task_command.py:426} INFO - Running <TaskInstance: 1_init_once_seed_data.load_seed_data_once manual__2024-05-10T15:29:36.514489+00:00 [running]> on host e4fe3fcdc4ab
[2024-05-10T15:29:38.100+0000] {taskinstance.py:2644} INFO - Exporting env vars: AIRFLOW_CTX_DAG_OWNER='***' AIRFLOW_CTX_DAG_ID='1_init_once_seed_data' AIRFLOW_CTX_TASK_ID='load_seed_data_once' AIRFLOW_CTX_EXECUTION_DATE='2024-05-10T15:29:36.514489+00:00' AIRFLOW_CTX_TRY_NUMBER='1' AIRFLOW_CTX_DAG_RUN_ID='manual__2024-05-10T15:29:36.514489+00:00'
[2024-05-10T15:29:38.102+0000] {taskinstance.py:430} INFO - ::endgroup::
[2024-05-10T15:29:38.103+0000] {subprocess.py:63} INFO - Tmp dir root location: /tmp
[2024-05-10T15:29:38.103+0000] {subprocess.py:75} INFO - Running command: ['/usr/bin/bash', '-c', 'cd /dbt && dbt seed --profiles-dir .']
[2024-05-10T15:29:38.108+0000] {subprocess.py:86} INFO - Output:
[2024-05-10T15:29:39.500+0000] {subprocess.py:93} INFO - [0m15:29:39  Running with dbt=1.7.14
[2024-05-10T15:29:39.973+0000] {subprocess.py:93} INFO - [0m15:29:39  Registered adapter: snowflake=1.7.3
[2024-05-10T15:29:39.981+0000] {subprocess.py:93} INFO - [0m15:29:39  Encountered an error:
[2024-05-10T15:29:39.981+0000] {subprocess.py:93} INFO - Runtime Error
[2024-05-10T15:29:39.982+0000] {subprocess.py:93} INFO -   Failed to read package: Runtime Error
[2024-05-10T15:29:39.982+0000] {subprocess.py:93} INFO -     This version of dbt is not supported with the 'dbt_utils' package.
[2024-05-10T15:29:39.982+0000] {subprocess.py:93} INFO -       Installed version of dbt: =1.7.14
[2024-05-10T15:29:39.982+0000] {subprocess.py:93} INFO -       Required version of dbt for 'dbt_utils': ['>=0.18.0', '<0.20.0']
[2024-05-10T15:29:39.983+0000] {subprocess.py:93} INFO -     Check for a different version of the 'dbt_utils' package, or run dbt again with --no-version-check
[2024-05-10T15:29:39.983+0000] {subprocess.py:93} INFO - 
[2024-05-10T15:29:39.983+0000] {subprocess.py:93} INFO - 
[2024-05-10T15:29:39.983+0000] {subprocess.py:93} INFO -   Error encountered in /dbt/dbt_packages/dbt_utils/dbt_project.yml
[2024-05-10T15:29:39.983+0000] {subprocess.py:93} INFO - 
[2024-05-10T15:29:39.984+0000] {subprocess.py:93} INFO - Error encountered in /dbt/dbt_packages/dbt_utils
[2024-05-10T15:29:42.103+0000] {subprocess.py:97} INFO - Command exited with return code 2
[2024-05-10T15:29:42.104+0000] {taskinstance.py:441} INFO - ::group::Post task execution logs
[2024-05-10T15:29:42.109+0000] {taskinstance.py:2890} ERROR - Task failed with exception
Traceback (most recent call last):
  File "/home/airflow/.local/lib/python3.12/site-packages/airflow/models/taskinstance.py", line 465, in _execute_task
    result = _execute_callable(context=context, **execute_callable_kwargs)
             ^^^^^^^^^^^^^^^^^^^^^^^^^^^^^^^^^^^^^^^^^^^^^^^^^^^^^^^^^^^^^
  File "/home/airflow/.local/lib/python3.12/site-packages/airflow/models/taskinstance.py", line 432, in _execute_callable
    return execute_callable(context=context, **execute_callable_kwargs)
           ^^^^^^^^^^^^^^^^^^^^^^^^^^^^^^^^^^^^^^^^^^^^^^^^^^^^^^^^^^^^
  File "/home/airflow/.local/lib/python3.12/site-packages/airflow/models/baseoperator.py", line 400, in wrapper
    return func(self, *args, **kwargs)
           ^^^^^^^^^^^^^^^^^^^^^^^^^^^
  File "/home/airflow/.local/lib/python3.12/site-packages/airflow/operators/bash.py", line 243, in execute
    raise AirflowException(
airflow.exceptions.AirflowException: Bash command failed. The command returned a non-zero exit code 2.
[2024-05-10T15:29:42.112+0000] {taskinstance.py:1205} INFO - Marking task as FAILED. dag_id=1_init_once_seed_data, task_id=load_seed_data_once, execution_date=20240510T152936, start_date=20240510T152937, end_date=20240510T152942
[2024-05-10T15:29:42.118+0000] {standard_task_runner.py:110} ERROR - Failed to execute job 101 for task load_seed_data_once (Bash command failed. The command returned a non-zero exit code 2.; 73)
[2024-05-10T15:29:42.162+0000] {local_task_job_runner.py:240} INFO - Task exited with return code 1
[2024-05-10T15:29:42.171+0000] {taskinstance.py:3482} INFO - 0 downstream tasks scheduled from follow-on schedule check
[2024-05-10T15:29:42.171+0000] {local_task_job_runner.py:222} INFO - ::endgroup::
